Workbook

Sheet Sheet1
A1: aэt | B1: =Sheet3!L89 -> 2.45 | C1: ارتفاع السقف, م | D1: kр.г | E1: =Sheet3!K56 -> 0.56 | F1: عامل التدمير للتربة حول الجدار | G1: Kp.pc | H1: =Sheet3!K55 -> 0 | I1: معامل تدمير طبقة توزيع الضغط | K1: Lk | L1: 50 | M1: طول المنشأة,م | O1: Bk | P1: 20 | Q1: عرض المنشأة,م
A2: bp | B2: =Sheet3!N89 -> 3 | C2: المجاز الطويل, م | D2: kр.бt | E2: =Sheet3!K54 -> 0 | F2: عامل التدمير لبيتون يلاطة الحماية | G2: A | H2: =L2 -> 5 | I2: عامل متعلق بتربة توزيع الضغط | K2: A | L2: 5 | M2: عامل متعلق بالتربة حول الجدار
A3: ap | B3: =Sheet3!P89 -> 1 | C3: المجاز القصير, م | D3: γοбс | E3: =Sheet3!Q94 -> 0 | F3: الوزن الحجمي لطبقة التمويه, كغ/م3 | G3: n1 | H3: =L3 -> 3 | I3: عامل متعلق بتربة توزيع الضغط | K3: n1 | L3: 3 | M3: عامل متعلق بالتربة حول الجدار | P3: استحدام البرنامج من ال(Sheet3)
A4: P | B4: =Sheet3!E23 -> 547 | C4: وزن القنبلة كغ | D4: γ p.c | E4: =Sheet3!N94 -> 0 | F4: الوزن الحجمي لطبقة توزيع الضغط, كغ/م3 | G4: μп | H4: =Sheet3!I121 -> 0.001 | I4: عامل متعلق ب (־hᴈ) للسقف | K4: μc | L4: =H4 -> 0.001 | M4: عامل متعلق ب (־hᴈ) للجدار | O4: دراسة الحمولة الحسابية على سقف النفق نتيجة انفجار قنبلة بعد اختراقها للتربة
A5: lk | B5: =Sheet3!G23 -> 1.37 | C5: طول جسم القنبلة, م | D5: C | E5: =Sheet3!M23 -> 270 | F5: وزن الحشوة في القنبلة, كغ | G5: ηп | H5: =Sheet3!M121 -> 0.006 | I5: عامل متعلق ب (־hᴈ) للسقف | K5: ηc | L5: =H5 -> 0.006 | M5: عامل متعلق ب (־hᴈ) للجدار
A6: lᴈ/dᴈ | B6: =Sheet3!I23 -> 2.8 | C6: وزن الحشوة الى قطرها | D6: hoбc | E6: =Sheet3!B89 -> 0 | F6: سماكة طبقة التمويه فوق البلاطة, م | G6: Kt.п | H6: =Sheet3!C116 -> 1 | I6: عامل متعلق ب (־hᴈ) للسقف | K6: Kt.п | L6: =H6 -> 1 | M6: عامل متعلق ب (־hᴈ) للجدار
A7: loб | B7: =Sheet3!F23 -> 2.46 | C7: طول القنبلة العام , م | D7: V | E7: =Sheet3!C32 -> 600 | F7: السرع الابتدائية لسقوط القنبلة, م/ث | G7: a0п | H7: =L7 -> 600 | I7: للسقف | K7: a0c | L7: =Sheet3!F68 -> 600 | M7: للجدار
A8: lгч/d | B8: =Sheet3!K23 -> 1 | C8: نسبة طول الرأس الحربي للقطر | D8: α | E8: =Sheet3!F32 -> 30 | F8: زاوية سقوط القنبلة, درجة | G8: a0п/a1п | H8: =L8 -> 2 | I8: a1п | J8: =H7/H8 -> 300 | K8: a0c/a1c | L8: =Sheet3!I68 -> 2 | M8: a1c | N8: =L7/L8 -> 300
A9: Hct | B9: =Sheet3!H89 -> 0.15 | C9: السماكة المبدأية للجدار الخارجي, م | D9: n0 | E9: 1.25 | F9: عامل متعلق بنوع بلاطة الحماية(جدول1) | G9: a0пz | H9: =Sheet3!K135 -> 680 | I9: يوضع بعد حسابات 5.5 | K9: a0cz | L9: =H9 -> 680 | M9: يوضع بعد حسابات 8.5
A10: Hвct | B10: 0.3 | C10: السماكة المبدأية للجدار الداخلي, م | D10: kвt.бt | E10: =Sheet3!I54 -> 0 | F10: عامل تصدع بيتون البلاطة من جهة الانفجار | G10: a1пz | H10: =Sheet3!K163 -> 350 | I10: يوضع بعد حسابات 5.5 | K10: a1cz | L10: =H10 -> 350 | M10: يوضع بعد حسابات 8.5
A11: Hф | B11: =Sheet3!F89 -> 0.15 | C11: السماكة المبدأية للأرضية, م | D11: dk | E11: =Sheet3!H23 -> 0.48 | F11: نصف قطر جسم القنبلة, م | G11: Ea | H11: =Sheet3!Q79 -> 2100000 | I11: عامل مرونة الحديد,كغ/سم2 | K11: ξ | L11: =Sheet3!J68 -> 0.55 | M11: معامل الضغط الجانبي لتربة الجدار
A12: Hп | B12: =Sheet3!J89 -> 0.15 | C12: السماكة المبدأية للسقف, م | D12: K1 | E12: =Sheet3!M29 -> 1.639 | F12: عامل قوة المادة المتفجرة في القنبلة نسبة للتراتيل | G12: ψп | H12: 0.008 | I12: نسبة تسليح البيتون مساحيا | K12: ρ,kg.s2/m4 | L12: =Sheet3!D69 -> 0 | M12: كثافة طبقة توزيع الضغط
A13: kпр.г | B13: =Sheet3!G56 -> 1.5e-06 | C13: معامل الاختراق للتربة | D13: kot.бt | F13: عامل تصدع البيتون من الجهة المعاكسة للانفجار | G13: السقف مع الجدار | H13: 1 | I13: وثاقة(1), متمفصل(2) | K13: ρ,kg.s2/m4 | L13: =Sheet3!D68 -> 180 | M13: كثافة التربة حول الجدار
A14: kпр.б | B14: =Sheet3!G57 -> 0 | C14: معامل اختراق بيتون السقف | D14: kot.г | F14: عامل تصدع التربة من الجهة المعاكسة للانفجار | G14: RsH | H14: =Sheet3!O79 -> 4000 | I14: مقاومة الحديد كغ/سم2 | K14: H | L14: =Sheet3!G94 -> 9.5 | M14: عمق توضع سقف النفق
A15: γб | B15: =Sheet3!R94 -> 2500 | C15: الوزن الحجمي للبيتون, كغ/م3 | D15: K kp.ct | E15: 1.1 | F15: عامل يتعلقق بطبيعة جدار المنشأة | G15: RbH | H15: =Sheet3!F77 -> 200 | I15: مقاومة البيتون كغ/سم2
A16: γг | B16: =Sheet3!P94 -> 2000 | C16: وزن حجمي لتربة الجدار, كغ/م3 | D16: m1 | E16: 1.65 | F16: عامل يتعلقق بطبيعة التربة المخترقة | G16: R٭־п | H16: =Sheet3!F109 -> 0.55 | I16: متعلق بتربة توزيع الضغط وتوضع قيمتها لاحقا بعد حساب ᴈ־hمن الفقرة5.1
A17: المعطيات الأساسية | G17: Kпοд.b | H17: =Sheet3!E194 -> 1.18 | I17: للسقف/بيتون | J17: Kпοд.b | K17: =H17 -> 1.18 | L17: للجدار/بيتون
G18: Kпοд.s | H18: =Sheet3!E192 -> 1.18 | I18: للسقف/حديد | J18: Kпοд.s | K18: =H18 -> 1.18 | L18: للجدار/حديد
G21: Pk | H21: =Sheet3!M84 -> 32.175 | I21: وزن المنشأة ,طن
G22: Kп,п | H22: =Sheet3!L208 -> 0.86 | I22: يوضع بعد حسابات 5.7
G23: Kд,п | H23: =Sheet3!K229 -> 0 | I23: معاما الديناميك يوضع بعد حسابات 5.9
G24: R٭־п | H24: =H16 -> 0.55 | I24: متعلق بتربة الجداروتوضع قيمتها لاحقا بعد حساب ᴈ־hمن الفقرة6.2
G25: Kп,c | H25: =H22 -> 0.86 | I25: يوضع بعد حسابات 8.7
G26: Kд,c | H26: =H23 -> 0 | I26: معاما الديناميك يوضع بعد حسابات.8.9
K34: يجب املاء جدول المعطيات الرئيسية | P34: 1
K36: تحديد عمق الاختراق في التربة | P36: 2
C38: ; ht = n0(rвt - ц)
D39: م | E39: =E40*E41*B13*(B4/(E11)^2)*E7*COS((E8)*(3.14/180)) -> 2.1523624 | F39: hпр.t = λ1*λ2*kпр.г*p/(d)^2*V*COS(α), m
E40: =0.5+0.4*((B8)^0.666) -> 0.9 | F40: λ1= 0.5+0.4*(lгч/d)^0.666
E41: =2.8*((E11)^0.333)-1.3*((E11)^0.5) -> 1.2921959 | F41: λ2 = 2.8*{(d)^0.33}-1.3*{(d)^0.5}
E42: =(3.5-(B8)) -> 2.5 | F42: n ={3.5 -lгч/d)
C43: اذا كان lᴈ/dᴈ اكبر من 3 فالحشوة متطاولة وإلا فالحشوة مجمعة
B44: Cэф= 0.95*k1*C | D44: =0.95*E12*E5 -> 420.4035 | F44: Cэф1= Cэф/lᴈ | G44: =D44/G46 -> 329.26339
A45: k1: عامل يتعلق بنوع المواد المتفجرة وهو لل ت ن ت يساوي 1.639 اي اقوى من التراتيل بهذا المقدار | L45: ц=0.5 lk*COS((α+nα)/2) | N45: =0.5*B5*COS((0.5*E8+0.5*E8*E42)*3.14/180) -> 0.41725398 | O45: m
F46: lᴈ=dᴈ*(lᴈ/dᴈ)=0.95dk*(lᴈ/dᴈ) | G46: =0.95*E11*B6 -> 1.2768 | H46: m
C48: m : هو عامل الدكة وهو يساوي 1.1 عندما تكون سماكة طبقة التمويه اكبر من 0.5 متر ويكون مساويا 1 عندما تكون اصغر او تساوي 0.5متر
E49: =1.65 -> 1.65
M83: حساب الحمولات على السقف | Q83: 3
J84: وتحديد نوع الموجة | M84: حساب التوتر الاعظمي في موجة الضغط maxбв | Q84: 3.1
H85: if h־ᴈ >= 0.7 | K85: maxбв=A*(R־)^-n1 | Q85: =H2*Q89^(-H3) -> 4.4627902
...

Sheet Sheet2
O18: منطقة الحمل الديناميكي
K21: النفق

Sheet Sheet3
O1: عزيزي المهندس الشاطر: يتم استخدام هذا البرنامج من خلال هذه الصفحة وستكون الإدخالات والمخرجات في هذه الصفحة ولاداعي لفتح الصفحة الاولى والثانية لأن اي كتابة او تعديل سيؤدي الى تخريب البرنامج
N2: ارجو منك الالتزام بطريقة العمل حسب ماسأكتبه ادناه. القيم الموضوعة هي لحالة دراسية معينة اما انت فاختر ماتريده وستتغير الارقام والحسابات بناء على دراستك انت.
Q4: ادخل المعطيات الاساسية بعد النظر الى الجداول والرسوم وضع قيم هذه المعطيات في المربعات المخصصة باللون الاحمر | R4: A
H6: جدول 1 | Q6: القنبلة المستخدمة: ان هذه الدراسة تخص القنابل الخارقة التي تخرق مسافة معينة في بلاطة الحماية وتنفجر بعد زمن | R6: A-1
C7: نوع القنبلة | D7: عياره(فونت) | E7: الوزن,كغ | F7: الطول العام, م | G7: طول الهيكل, م | H7: قطر الهيكل,م | I7: نسبة طول الحشوة الى قطر الهيكل | K7: نسبة طول الرأس الحربي الى القطر | M7: وزن المواد المتفجرة, كغ | O7: نوع المادة المتفجرة
B8: الترميز | C8: _ | D8: _ | E8: P | F8: loб | G8: lk | H8: dk | I8: lᴈ/dk | K8: lгч/dk | M8: C | O8: _
B9: 1 | C9: AN-M30A1 | D9: 100 | E9: 61 | F9: 1.38 | G9: 0.76 | H9: 0.21 | I9: 3.6 | K9: 1 | M9: 23 | O9: تريتونال
B10: =1+B9 -> 2 | C10: AN-M57A1 | D10: 250 | E10: 131 | F10: 1.58 | G10: 0.95 | H10: 0.28 | I10: 3.4 | K10: 1 | M10: 62 | O10: تريتونال
B11: =1+B10 -> 3 | C11: AN-M64A1 | D11: 500 | E11: 264 | F11: 1.83 | G11: 1.21 | H11: 0.36 | I11: 3.3 | K11: 1 | M11: 128 | O11: تريتونال
B12: =1+B11 -> 4 | C12: M117(M) | D12: 750 | E12: 373 | F12: 2.27 | G12: 1.42 | H12: 0.41 | I12: 3.5 | K12: 1 | M12: 177 | O12: تريتونال
B13: =1+B12 -> 5 | C13: AN-M65A1 | D13: 1000 | E13: 547 | F13: 2.46 | G13: 1.37 | H13: 0.48 | I13: 2.8 | K13: 1 | M13: 270 | O13: تريتونال
B14: =1+B13 -> 6 | C14: AN-M66A1 | D14: 2000 | E14: 1033 | F14: 2.97 | G14: 1.82 | H14: 0.59 | I14: 3.1 | K14: 1 | M14: 526 | O14: تريتونال
B15: =1+B14 -> 7 | C15: _ | D15: 3000 | E15: 1383 | F15: 4.7 | G15: 3.07 | H15: 0.61 | I15: 5 | K15: 1 | M15: 816 | O15: تريتونال
B16: =1+B15 -> 8 | C16: MK81 | D16: 250 | E16: 118 | F16: 1.88 | G16: 1.18 | H16: 0.23 | I16: 5.2 | K16: 2.5 | M16: 45 | O16: تريتونال
B17: =1+B16 -> 9 | C17: MK82 | D17: 500 | E17: 241 | F17: 2.21 | G17: 1.55 | H17: 0.27 | I17: 5.7 | K17: 2.5 | M17: 87 | O17: تريتونال
B18: =1+B17 -> 10 | C18: MK83 | D18: 1000 | E18: 441 | F18: 3.01 | G18: 1.92 | H18: 0.36 | I18: 5.3 | K18: 2 | M18: 215 | O18: تريتونال
B19: =1+B18 -> 11 | C19: MK84 | D19: 2000 | E19: 894 | F19: 3.83 | G19: 2.41 | H19: 0.46 | I19: 5.2 | K19: 2 | M19: 430 | O19: تريتونال
B20: =1+B19 -> 12 | C20: MK81 سنيكاي | D20: 250 | E20: 134 | F20: 1.91 | G20: 1.19 | H20: 0.23 | I20: 5.2 | K20: 2.5 | M20: 45 | O20: تريتونال
B21: =1+B20 -> 13 | C21: MK82 سنيكاي | D21: 500 | E21: 260 | F21: 2.26 | G21: 1.55 | H21: 0.27 | I21: 5.7 | K21: 2.5 | M21: 87 | O21: تريتونال
B22: =1+B21 -> 14 | C22: M117R | D22: 750 | E22: 380 | F22: 2.21 | G22: 1.12 | H22: 0.11 | I22: 3.5 | K22: 1 | M22: 177 | O22: تريتونال
E23: 547 | F23: 2.46 | G23: 1.37 | H23: 0.48 | I23: 2.8 | K23: 1 | M23: 270
R24: ملاحظة: اذا كانت القنيلة المطلوبة غير موجودة في الجدول يجب معرفة مواصفاتها ووضعها في المربعات الحمر
F26: جدول رقم 2 | N26: جدول رقم3
B27: للقنابل الغير الموجهة V تساوي 250-300 م/ثا اما α فتساوي 20-30 درجة | L27: نوع المادة المتفجرة | N27: تريتونال 80-20 | O27: خليط v | P27: تورليكس H6 | Q27: تريتونال 90/40 | R27: ايدنالود
D28: اما للقنابل الموجهة فحسب الجدول | I28: للصواريخ | L28: معامل المادة المتفجرة-K1 | N28: 1.639 | O28: 1.34 | P28: 1.26 | Q28: 1.23 | R28: 1.05
D29: م/ثا ,V | E29: 300-400 | F29: 400-600 | I29: V | J29: α | L29: K1= | M29: 1.639
D30: درجة,α | E30: 25-40 | F30: 30-45 | I30: 790-940 | J30: 40-60 | R30: جدول 3 يبين قوة المادة المتفجرة في القنبلة منسوبا الى التراتيل
B32: V= | C32: 600 | E32: α= | F32: 30
J34: جدول 2 يبين السرعة الابتدائية لسقوط القنبلة وزاوية الميل عن الشاقول عند الاصطدام بالارض
Q35: مواصفات والمعاملات الخاصة بالتربة والبيتون و حديد التسليح | R35: A-2
G38: جدول رقم 5
C39: نوع المادة | G39: معامل الاختراق | I39: معامل التصدع من جهة الانفجار | K39: معامل التدمير | L39: معامل التصدع من الجهة المعاكسة
E40: الترميز | G40: Kпp | I40: Kв | K40: Kp | M40: Kot
C41: طين رخو مشبع بالماء | G41: 1.3e-05 | I41: 0.6 | K41: 0.85 | M41: _
C42: طين متوسط الكثافة | G42: 7e-06 | I42: 0.5 | K42: 0.6 | M42: _
C43: طبقة طينية طبيعية مع وجود احجار في تشكيلها | G43: 6e-06 | I43: 0.5 | K43: 0.6 | M43: _
C44: طبقة رمل مخلط بالشوائب | G44: 5e-06 | I44: 0.5 | K44: 0.6 | M44: _
C45: طبقة رمل نقي طبيعي/او طبقة كلسية مفتتة | G45: 4.5e-06 | I45: 0.5 | K45: 0.63 | M45: _
C46: طبقة من البلوك او الاحجارة المرصوفة | G46: 3e-06 | I46: 0.25 | K46: 0.58 | M46: 0.88 | P46: جدول رقم 6
C47: طبقة بلوك او احجارة مرصوفة مع استخدام الاسمنت | G47: 2.5e-06 | I47: 0.25 | K47: 0.61 | M47: 0.81 | N47: نوع التربة | Q47: A | R47: n1
...

Sheet ورقة1
B1: دراسة المنشأة النفقية لمشروع الخزانات المائية3(الانفاق الاضافية)
A3: المعطيات الاساسية:
A4: 1- | B4: نوع ومواصفات القنبلة المستخدمة:
A5: نوع القنبلة | B5: عياره(فونت) | C5: الوزن,كغ | D5: الطول العام, م | E5: طول الهيكل, م | F5: قطر الهيكل,م | G5: نسبة طول الحشوة | H5: نسبة طول الراس | I5: وزن الحشوة,كغ
G6: الى الهيكل | H6: الحربي ال القطر
C7: P | D7: loб | E7: lk | F7: dk | G7: lᴈ/dk | H7: lгч/dk | I7: C
A8: MK83 | B8: 1000 | C8: =Sheet3!E23 -> 547 | D8: =Sheet3!F23 -> 2.46 | E8: =Sheet3!G23 -> 1.37 | F8: =Sheet3!H23 -> 0.48 | G8: =Sheet3!I23 -> 2.8 | H8: =Sheet3!K23 -> 1 | I8: =Sheet3!M23 -> 270
A10: نوع المادة المتفجرة | C10: تريتونال
A11: معامل المادة المتفجرة-K1 | C11: 1.639
B12: =Sheet3!C32 -> 600 | C12: ,V= | D12: السرعة الابتدائية للقنبلة | F12: م/ثا
B13: =Sheet3!F32 -> 30 | C13: α= | D13: زاوية سقوط القنبلة | F13: درجة
A15: 2- | B15: نوع ومواصفات التربة
B16: تسمية التربة | C16: معامل الاختراق | D16: معامل التصدع | E16: معامل التصدع | F16: معامل التدمير | G16: عامل تجريبي1 | H16: عامل تجريبي2 | I16: سرعة المواج
D17: المواجه | E17: العكسي | I17: الطولية المرنة
C18: Kпp | D18: Kв | E18: Kot | F18: Kp | G18: n1 | H18: A | I18: a0, م/ثا
C19: =Sheet3!G56 -> 1.5e-06 | D19: =Sheet3!I56 -> 0.25 | E19: =Sheet3!M56 -> 0.79 | F19: =Sheet3!K56 -> 0.56 | G19: =Sheet3!R52 -> 3 | H19: =Sheet3!Q52 -> 5 | I19: =Sheet3!F68 -> 600
C20: نسبة
C21: a0/a1 | D21: =Sheet3!I68 -> 2
A22: 3- | B22: مواصفات البيتون وحديد التسليح
B23: معامل مرونة | C23: مقاومة الشد حد | D23: مقاومة الضغط
B24: الحديد كغ/سم2 | C24: السيولة كغ/سم2 | D24: للبيتون كغ/سم2
B25: =Sheet3!Q79 -> 2100000 | C25: =Sheet3!O79 -> 4000 | D25: =Sheet3!F77 -> 200
A26: 4- | B26: ابعاد المنشأة
B27: عرض,م | C27: طول,م | D27: ارتفاع,م | E27: سماكة السقف | F27: سماكة الجدران | G27: سماكة الارضية | H27: نسبة التسليح
E28: الاولية | F28: الاولية | G28: الاولية | H28: الاولية
B29: =Sheet3!P89 -> 1 | C29: =Sheet3!N89 -> 3 | D29: =Sheet3!L89 -> 2.45 | E29: =Sheet3!J89 -> 0.15 | F29: =Sheet3!H89 -> 0.15 | G29: =Sheet3!F89 -> 0.15 | H29: =Sheet3!D89 -> 0.009
A31: الحسابات:
A32: 1 | B32: تحديد عمق الاختراق في التربة
B34: =Sheet1!E39 -> 2.1523624 | G34: hпр.t = λ1*λ2*kпр.г*p/(d)^2*V*COS(α), m
B35: =Sheet1!E41 -> 1.2921959 | E35: λ2 = 2.8*{(d)^0.33}-1.3*{(d)^0.5}
B36: =Sheet1!E40 -> 0.9 | C36: λ1= 0.5+0.4*(lгч/d)^0.666
B37: =Sheet1!E42 -> 2.5 | F37: n ={3.5 -lгч/d)
B38: =Sheet1!G44 -> 329.26339 | F38: Cэф1= Cэф/lᴈ
B39: =Sheet1!D44 -> 420.4035 | D39: Cэф= 0.95*k1*C
B40: =Sheet1!G46 -> 1.2768 | F40: lᴈ=dᴈ*(lᴈ/dᴈ)=0.95dk*(lᴈ/dᴈ)
B41: =Sheet1!N45 -> 0.41725398 | D41: ц=0.5 lk*COS((α+nα)/2) | F41: م
A43: 2 | B43: حساب الحمولات على السقف
B44: =Sheet1!Q92 -> 4.4181623 | G44: maxбв=A*(R־)^-n1
B45: =Sheet1!Q87 -> 0.23208428 | E45: h־ᴈ =hᴈ/(Cэф)^0.333
B46: =Sheet1!Q91 -> 4.1119098 | F46: R٭=R٭־(Cэф)^0.333
...

Sheet ورقة2
