Workbook

Sheet Sheet1

Sheet Sheet2
Q1: β | R1: K1 | S1: R̽¯ | T1: kp.г | U1: d | V1: P | W1: V | X1: α | Y1: C | Z1: lk | AA1: knp.г | AB1: lгч/d
Q2: =Sheet3!M80 -> 22 | R2: =Sheet3!M29 -> 1.639 | S2: =Sheet3!F80 -> 1.1 | T2: =Sheet3!K54 -> 0.56 | U2: =Sheet3!H23 -> 0.36 | V2: =Sheet3!E23 -> 441 | W2: =Sheet3!C32 -> 600 | X2: =Sheet3!F32 -> 30 | Y2: =Sheet3!M23 -> 215 | Z2: =Sheet3!G23 -> 1.92 | AA2: =Sheet3!G54 -> 1.5e-06 | AB2: =Sheet3!K23 -> 2
W8: H =(R̽ +hpr -ц) | AB8: =IF(AB25>AB10,AB25+AB16-AB14,AB10+AB16-AB14) -> 10.31263
W10: R̽ = R̽¯ *(Cэф)^0.333 | AB10: =S2*POWER(AB12,0.333) -> 7.623097
W12: Cэф = K1*0.95*C | AB12: =R2*0.95*Y2 -> 334.76575
W14: ц = 0.5*lk*cosα | AB14: =0.5*Z2*COS(X3*3.14/180) -> 0.96
W16: hпр = λ1*λ2*kпр.г*p/(d)^2*V*COSα, m | AB16: =AB17*AB18*AA2*V2*W2*(COS(X2*3.14/180))/U2^2 -> 3.6495333
X17: λ1= 0.5+0.4*(lгч/d)^0.666 | AB17: =0.5+0.4*((AB2)^0.666) -> 1.1346671
X18: λ2 = 2.8*{(d)^0.333}-1.3*{(d)^0.5} | AB18: =2.8*((U2)^0.333)-1.3*((U2)^0.5) -> 1.2125387
X20: hз¯ =hз/(Cэф)^0.333 | AB20: =AB21/(AB12)^0.333 -> 0.3880951
X21: hз =hnp -ц | AB21: =AB16-AB14 -> 2.6895333
P22: النفق
W23: تحقيق الشرط | Y23: R̽ > Zp
W25: للتربة | X25: Zp = 1.5* kp.г*(Cэф)^0.333 | AB25: =1.5*T2*((AB12)^0.333) -> 5.8212741
W26: المكافئة(تربة مع بيتون) | X26: Zp ekv = Zp
X27: L = H/tanβ | AB27: =AB8/TAN(Q2*3.14/180) -> 25.538967
X30: الفرق بين عمق توضع النفق و عمق الاختراق | Y30: Z-hnp=Y = | AB30: =Sheet3!Q79-Sheet2!AB16 -> 0.050466745 | AC30: m
Q31: اذا كانت النتيجة سالبة فهذا يعني ان المنشأة خارج نطاق قطر التدمير | X31: سماكة البيتون بالنسبة للتدمير(اي ان التدمير لسماكة المقطع مسموحة دون نفوذ قوة التفجير للداخل) | Y31: hb=(Zp -Y)*(Kp beton/Kp rock) | AC31: =(AB25-AB30)*(Sheet3!K55/Sheet3!K54) -> 3.2976042 | AD31: m
Q32: اذا كانت النتيجة سالبة فهذا يعني ان المنشأة خارج نطاق قطر التصدع | X32: سماكة البيتون بالنسبة للتصدع(اي ان التصدع المقطع مسموح دون حصول تدميره) | Y32: hb=(Zot. rock -Y)*(Kot beton/Kot rock) | AC32: =(AB34-AB30)*(S35/S34) -> 4.7523751 | AD32: m
R34: Kot rock | S34: =Sheet3!M54 -> 0.79 | W34: Zot. Rock = | X34: 1.5* kot.г*(Cэф)^0.333 | AB34: =(AB12^0.333)*1.5*S34 -> 8.2121545 | AC34: m
R35: Kot beton | S35: =Sheet3!M55 -> 0.46

Sheet Sheet3
A1: عزيزي المهندس الشاطر: يتم استخدام هذا البرنامج من خلال هذه الصفحة وستكون الإدخالات والمخرجات في هذه الصفحة ولاداعي لفتح الصفحة الاولى والثانية لأن اي كتابة او تعديل سيؤدي الى تخريب البرنامج
N2: ارجو منك الالتزام بطريقة العمل حسب ماسأكتبه ادناه. القيم الموضوعة هي لحالة دراسية معينة اما انت فاختر ماتريده وستتغير الارقام والحسابات بناء على دراستك انت.
Q4: ادخل المعطيات الاساسية بعد النظر الى الجداول والرسوم وضع قيم هذه المعطيات في المربعات المخصصة باللون الاحمر | R4: A
H6: جدول 1 | Q6: القنبلة المستخدمة: ان هذه الدراسة تخص القنابل الخارقة التي تخرق مسافة معينة في بلاطة الحماية وتنفجر بعد زمن | R6: A-1
C7: نوع القنبلة | D7: عياره(فونت) | E7: الوزن,كغ | F7: الطول العام, م | G7: طول الهيكل, م | H7: قطر الهيكل,م | I7: نسبة طول الحشوة الى قطر الهيكل | K7: نسبة طول الرأس الحربي الى القطر | M7: وزن المواد المتفجرة, كغ | O7: نوع المادة المتفجرة
B8: الترميز | C8: _ | D8: _ | E8: P | F8: loб | G8: lk | H8: dk | I8: lᴈ/dk | K8: lгч/dk | M8: C | O8: _
B9: 1 | C9: AN-M30A1 | D9: 100 | E9: 61 | F9: 1.38 | G9: 0.76 | H9: 0.21 | I9: 3.6 | K9: 1 | M9: 23 | O9: تريتونال
B10: =1+B9 -> 2 | C10: AN-M57A1 | D10: 250 | E10: 131 | F10: 1.58 | G10: 0.95 | H10: 0.28 | I10: 3.4 | K10: 1 | M10: 62 | O10: تريتونال
B11: =1+B10 -> 3 | C11: AN-M64A1 | D11: 500 | E11: 264 | F11: 1.83 | G11: 1.21 | H11: 0.36 | I11: 3.3 | K11: 1 | M11: 128 | O11: تريتونال
B12: =1+B11 -> 4 | C12: M117(M) | D12: 750 | E12: 373 | F12: 2.27 | G12: 1.42 | H12: 0.41 | I12: 3.5 | K12: 1 | M12: 177 | O12: تريتونال
B13: =1+B12 -> 5 | C13: AN-M65A1 | D13: 1000 | E13: 547 | F13: 2.46 | G13: 1.37 | H13: 0.48 | I13: 2.8 | K13: 1 | M13: 270 | O13: تريتونال
B14: =1+B13 -> 6 | C14: AN-M66A1 | D14: 2000 | E14: 1033 | F14: 2.97 | G14: 1.82 | H14: 0.59 | I14: 3.1 | K14: 1 | M14: 526 | O14: تريتونال
B15: =1+B14 -> 7 | C15: _ | D15: 3000 | E15: 1383 | F15: 4.7 | G15: 3.07 | H15: 0.61 | I15: 5 | K15: 1 | M15: 816 | O15: تريتونال
B16: =1+B15 -> 8 | C16: MK81 | D16: 250 | E16: 118 | F16: 1.88 | G16: 1.18 | H16: 0.23 | I16: 5.2 | K16: 2.5 | M16: 45 | O16: تريتونال
B17: =1+B16 -> 9 | C17: MK82 | D17: 500 | E17: 241 | F17: 2.21 | G17: 1.55 | H17: 0.27 | I17: 5.7 | K17: 2.5 | M17: 87 | O17: تريتونال
B18: =1+B17 -> 10 | C18: MK83 | D18: 1000 | E18: 441 | F18: 3.01 | G18: 1.92 | H18: 0.36 | I18: 5.3 | K18: 2 | M18: 215 | O18: تريتونال
B19: =1+B18 -> 11 | C19: MK84 | D19: 2000 | E19: 894 | F19: 3.83 | G19: 2.41 | H19: 0.46 | I19: 5.2 | K19: 2 | M19: 430 | O19: تريتونال
B20: =1+B19 -> 12 | C20: MK81 سنيكاي | D20: 250 | E20: 134 | F20: 1.91 | G20: 1.19 | H20: 0.23 | I20: 5.2 | K20: 2.5 | M20: 45 | O20: تريتونال
B21: =1+B20 -> 13 | C21: MK82 سنيكاي | D21: 500 | E21: 260 | F21: 2.26 | G21: 1.55 | H21: 0.27 | I21: 5.7 | K21: 2.5 | M21: 87 | O21: تريتونال
B22: =1+B21 -> 14 | C22: M117R | D22: 750 | E22: 380 | F22: 2.21 | G22: 1.12 | H22: 0.11 | I22: 3.5 | K22: 1 | M22: 177 | O22: تريتونال
E23: 441 | G23: 1.92 | H23: 0.36 | K23: 2 | M23: 215
R24: ملاحظة: اذا كانت القنيلة المطلوبة غير موجودة في الجدول يجب معرفة مواصفاتها ووضعها في المربعات الحمر
F26: جدول رقم 2 | N26: جدول رقم3
B27: للقنابل الغير الموجهة V تساوي 250-300 م/ثا اما α فتساوي 20-30 درجة | L27: نوع المادة المتفجرة | N27: تريتونال 80-20 | O27: خليط v | P27: تورليكس H6 | Q27: تريتونال 90/40 | R27: ايدنالود
D28: اما للقنابل الموجهة فحسب الجدول | L28: معامل المادة المتفجرة-K1 | N28: 1.639 | O28: 1.34 | P28: 1.26 | Q28: 1.23 | R28: 1.05
D29: م/ثا ,V | E29: 300-400 | F29: 400-600 | G29: 790-940 | L29: K1= | M29: 1.639
D30: درجة,α | E30: 25-40 | F30: 30-45 | G30: 40-60 | R30: جدول 3 يبين قوة المادة المتفجرة في القنبلة منسوبا الى التراتيل
G31: للصواريخ
B32: V= | C32: 600 | E32: α= | F32: 30
J34: جدول 2 يبين السرعة الابتدائية لسقوط القنبلة وزاوية الميل عن الشاقول عند الاصطدام بالارض
Q35: مواصفات والمعاملات الخاصة بالتربة والبيتون و حديد التسليح | R35: A-2
G38: جدول رقم 4
C39: نوع المادة | G39: معامل الاختراق | I39: معامل التصدع من جهة الانفجار | K39: معامل التدمير | L39: معامل التصدع من الجهة المعاكسة
E40: الترميز | G40: Kпp | I40: Kв | K40: Kp | M40: Kot
C41: طين رخو مشبع بالماء | G41: 1.3e-05 | I41: 0.6 | K41: 0.85 | M41: _
C42: طين متوسط الكثافة | G42: 7e-06 | I42: 0.5 | K42: 0.6 | M42: _
C43: طبقة طينية طبيعية مع وجود احجار في تشكيلها | G43: 6e-06 | I43: 0.5 | K43: 0.6 | M43: _
C44: طبقة رمل مخلط بالشوائب | G44: 5e-06 | I44: 0.5 | K44: 0.6 | M44: _
C45: طبقة رمل نقي طبيعي/او طبقة كلسية | G45: 4.5e-06 | I45: 0.5 | K45: 0.63 | M45: _
C46: طبقة من البلوك او الاحجارة المرصوفة | G46: 3e-06 | I46: 0.25 | K46: 0.58 | M46: 0.88
...
