Workbook

Sheet Sheet1
A1: aэt | B1: =Sheet3!L89 -> 3 | C1: ارتفاع السقف, م | D1: kр.г | E1: =Sheet3!K56 -> 0.56 | F1: عامل التدمير للتربة حول الجدار | G1: Kp.pc | H1: =Sheet3!K55 -> 0.6 | I1: معامل تدمير طبقة توزيع الضغط | K1: Lk | L1: 50 | M1: طول المنشأة,م | O1: Bk | P1: 20 | Q1: عرض المنشأة,م
A2: bp | B2: =Sheet3!N89 -> 5 | C2: المجاز الطويل, م | D2: kр.бt | E2: =Sheet3!K54 -> 0.32 | F2: عامل التدمير لبيتون يلاطة الحماية | G2: A | H2: 3 | I2: عامل متعلق بتربة توزيع الضغط | K2: A | L2: 5 | M2: عامل متعلق بالتربة حول الجدار
A3: ap | B3: =Sheet3!P89 -> 4 | C3: المجاز القصير, م | D3: γοбс | E3: =Sheet3!Q94 -> 1500 | F3: الوزن الحجمي لطبقة التمويه, كغ/م3 | G3: n1 | H3: 3 | I3: عامل متعلق بتربة توزيع الضغط | K3: n1 | L3: 3 | M3: عامل متعلق بالتربة حول الجدار
A4: P | B4: =Sheet3!E23 -> 441 | C4: وزن القنبلة كغ | D4: γ p.c | E4: =Sheet3!N94 -> 1500 | F4: الوزن الحجمي لطبقة توزيع الضغط, كغ/م3 | G4: μп | H4: =Sheet3!I121 -> 0.025 | I4: عامل متعلق ب (־hᴈ) للسقف | K4: μc | L4: =Sheet3!I122 -> 0.009 | M4: عامل متعلق ب (־hᴈ) للجدار
A5: lk | B5: =Sheet3!G23 -> 1.92 | C5: طول جسم القنبلة, م | D5: C | E5: =Sheet3!M23 -> 215 | F5: وزن الحشوة في القنبلة, كغ | G5: ηп | H5: =Sheet3!M121 -> 0.015 | I5: عامل متعلق ب (־hᴈ) للسقف | K5: ηc | L5: =Sheet3!M122 -> 0.001 | M5: عامل متعلق ب (־hᴈ) للجدار
A6: lᴈ/dᴈ | B6: =Sheet3!I23 -> 5.3 | C6: وزن الحشوة الى قطرها | D6: hoбc | E6: =Sheet3!B89 -> 0.5 | F6: سماكة طبقة التمويه فوق البلاطة, م | G6: Kt.п | H6: =Sheet3!C116 -> 1 | I6: عامل متعلق ب (־hᴈ) للسقف | K6: Kt.п | L6: =Sheet3!C117 -> 1.1 | M6: عامل متعلق ب (־hᴈ) للجدار
A7: loб | B7: =Sheet3!F23 -> 3.01 | C7: طول القنبلة العام , م | D7: V | E7: =Sheet3!C32 -> 350 | F7: السرع الابتدائية لسقوط القنبلة, م/ث | G7: a0п | H7: =Sheet3!F69 -> 125 | I7: للسقف | K7: a0c | L7: =Sheet3!F68 -> 500 | M7: للجدار
A8: lгч/d | B8: =Sheet3!K23 -> 2 | C8: نسبة طول الرأس الحربي للقطر | D8: α | E8: =Sheet3!F32 -> 20 | F8: زاوية سقوط القنبلة, درجة | G8: a0п/a1п | H8: =Sheet3!I69 -> 3 | I8: a1п | J8: =H7/H8 -> 41.666667 | K8: a0c/a1c | L8: =Sheet3!I68 -> 2 | M8: a1c | N8: =L7/L8 -> 250
A9: Hct | B9: =Sheet3!H89 -> 0.5 | C9: السماكة المبدأية للجدار الخارجي, م | D9: n0 | E9: 1.25 | F9: عامل متعلق بنوع بلاطة الحماية(جدول1) | G9: a0пz | H9: =Sheet3!K135 -> 180 | I9: يوضع بعد حسابات 5.5 | K9: a0cz | L9: =Sheet3!K137 -> 580 | M9: يوضع بعد حسابات 8.5
A10: Hвct | B10: 0.3 | C10: السماكة المبدأية للجدار الداخلي, م | D10: kвt.бt | E10: =Sheet3!I54 -> 0.13 | F10: عامل تصدع بيتون البلاطة من جهة الانفجار | G10: a1пz | H10: =Sheet3!K163 -> 80 | I10: يوضع بعد حسابات 5.5 | K10: a1cz | L10: =Sheet3!K165 -> 290 | M10: يوضع بعد حسابات 8.5
A11: Hф | B11: =Sheet3!F89 -> 0.45 | C11: السماكة المبدأية للأرضية, م | D11: dk | E11: =Sheet3!H23 -> 0.36 | F11: نصف قطر جسم القنبلة, م | G11: Ea | H11: =Sheet3!Q79 -> 2100000 | I11: عامل مرونة الحديد,كغ/سم2 | K11: ξ | L11: =Sheet3!J68 -> 0.55 | M11: معامل الضغط الجانبي لتربة الجدار
A12: Hп | B12: =Sheet3!J89 -> 0.75 | C12: السماكة المبدأية للسقف, م | D12: K1 | E12: =Sheet3!M29 -> 1.639 | F12: عامل قوة المادة المتفجرة في القنبلة نسبة للتراتيل | G12: ψп | H12: =Sheet3!D89 -> 0.012 | I12: نسبة تسليح البيتون مساحيا | K12: ρ,kg.s2/m4 | L12: =Sheet3!D69 -> 150 | M12: كثافة طبقة توزيع الضغط
A13: kпр.г | B13: =Sheet3!G56 -> 1.8e-06 | C13: معامل الاختراق للتربة | D13: kot.бt | F13: عامل تصدع البيتون من الجهة المعاكسة للانفجار | G13: السقف مع الجدار | H13: 1 | I13: وثاقة(1), متمفصل(2) | K13: ρ,kg.s2/m4 | L13: =Sheet3!D68 -> 180 | M13: كثافة التربة حول الجدار
A14: kпр.б | B14: =Sheet3!G57 -> 8e-07 | C14: معامل اختراق بيتون السقف | D14: kot.г | F14: عامل تصدع التربة من الجهة المعاكسة للانفجار | G14: RsH | H14: =Sheet3!O79 -> 3000 | I14: مقاومة الحديد كغ/سم2 | K14: kпр.бt | L14: =Sheet3!G54 -> 8e-07 | M14: معامل اختراق بيتون بلاطة الحماية
A15: γб | B15: =Sheet3!R94 -> 2500 | C15: الوزن الحجمي للبيتون, كغ/م3 | D15: K kp.ct | E15: 1.1 | F15: عامل يتعلقق بطبيعة جدار المنشأة | G15: RbH | H15: =Sheet3!F77 -> 200 | I15: مقاومة البيتون كغ/سم2
A16: γг | B16: =Sheet3!P94 -> 1700 | C16: وزن حجمي لتربة الجدار, كغ/م3 | D16: m1 | E16: 1.65 | F16: عامل يتعلقق بطبيعة التربة المخترقة | G16: R٭־п | H16: =Sheet3!F109 -> 0.35 | I16: متعلق بتربة توزيع الضغط وتوضع قيمتها لاحقا بعد حساب ᴈ־hمن الفقرة5.1
A17: المعطيات الأساسية | G17: Kпοд.b | H17: =Sheet3!E194 -> 1.18 | I17: للسقف/بيتون | J17: Kпοд.b | K17: =Sheet3!E195 -> 1.18 | L17: للجدار/بيتون
G18: Kпοд.s | H18: =Sheet3!E192 -> 1.25 | I18: للسقف/حديد | J18: Kпοд.s | K18: =Sheet3!E193 -> 1.25 | L18: للجدار/حديد
G21: Pk | H21: =Sheet3!M84 -> 492.25 | I21: وزن المنشأة ,طن
G22: Kп,п | H22: =Sheet3!L208 -> 0.8 | I22: يوضع بعد حسابات 5.7
G23: Kд,п | H23: =Sheet3!K229 -> 0.92 | I23: معاما الديناميك يوضع بعد حسابات 5.9
G24: R٭־п | H24: =Sheet3!F110 -> 0.9 | I24: متعلق بتربة الجداروتوضع قيمتها لاحقا بعد حساب ᴈ־hمن الفقرة6.2
G25: Kп,c | H25: =Sheet3!L209 -> 1 | I25: يوضع بعد حسابات 8.7
G26: Kд,c | H26: =Sheet3!K230 -> 1 | I26: معاما الديناميك يوضع بعد حسابات.8.9
K34: يجب املاء جدول المعطيات الرئيسية | P34: 1
K36: تحديد سماكة بلاطة الحماية | P36: 2
C38: ; ht = n0(rвt - ц) | K38: ht = hnp.t+n0(Zвt -ц) | Q38: =IF(B6>3,E39+E9*(N43-N45),E39+E9*(N41-N45)) -> 1.0721671 | R38: m
D39: م | E39: =E40*E41*B14*(B4/(E11)^2)*E7*COS((0.5*E8+0.5*E8*E42)*(3.14/180)) -> 1.1881634 | F39: hпр.t = λ1*λ2*kпр.t*p/(d)^2*V*COS((α+nα)/2), m | I39: حيث n0 عامل احتياط يؤخذ من الجدول رقم (1),rвt: نصف قطر الحفرة المتكونة
E40: =0.5+0.4*((B8)^0.666) -> 1.1346671 | F40: λ1= 0.5+0.4*(lгч/d)^0.666
E41: =2.8*((E11)^0.333)-1.3*((E11)^0.5) -> 1.2125387 | F41: λ2 = 2.8*{(d)^0.33}-1.3*{(d)^0.5} | H41: للحشوة المجمعة | J41: rвt= m kвt.бt( (Cэф)^0.3333) | N41: =E49*E10*(D44)^0.3333 -> 0.99273245 | O41: m
E42: =(3.5-(B8)) -> 1.5 | F42: n ={3.5 -lгч/d)
C43: اذا كان lᴈ/dᴈ اكبر من 3 فالحشوة متطاولة وإلا فالحشوة مجمعة | H43: للحشوة المتطاولة | J43: rвt=0.4 m kвt.бt (Cэф1)^0.5 | N43: =0.4*E49*E10*(G44)^0.5 -> 0.77734812 | O43: m
B44: Cэф= 0.95*k1*C | D44: =0.95*E12*E5 -> 334.76575 | F44: Cэф1= Cэф/lᴈ | G44: =D44/G46 -> 184.68816
A45: k1: عامل يتعلق بنوع المواد المتفجرة وهو لل ت ن ت يساوي 1.639 اي اقوى من التراتيل بهذا المقدار | L45: ц=0.5 lk*COS((α+nα)/2) | N45: =0.5*B5*COS((0.5*E8+0.5*E8*E42)*3.14/180) -> 0.8701452 | O45: m
F46: lᴈ=dᴈ*(lᴈ/dᴈ)=0.95dk*(lᴈ/dᴈ) | G46: =0.95*E11*B6 -> 1.8126 | H46: m
C48: m : هو عامل الدكة وهو يساوي 1.1 عندما تكون سماكة طبقة التمويه اكبر من 0.5 متر ويكون مساويا 1 عندما تكون اصغر او تساوي 0.5متر
E49: =IF(E6<0.5,1,1.1) -> 1.1
P53: تحديد بروز بلاطة الحماية Bt | Q53: 3
K55: انظر المخطط(1) | N55: Bt =R0 +Zt, m | Q55: =F57+F62 -> 8.0520158 | R55: m
D56: بعد الجدار الآمن عن القنبلة | F56: R0 = K kp.ct*Zp.гp, m | G56: : عامل يتعلق بطبيعة جدار المنشأة من الصفحة 162 الجدول 25 Kkp.ct
...

Sheet Sheet2
A1: 0 | B1: 1 | C1: 2 | D1: 4 | E1: 6 | F1: 8 | G1: 10 | H1: 12
A2: 0 | B2: 0.8 | C2: 1.05 | D2: 1 | E2: 0.95 | F2: 0.92 | G2: 0.93 | H2: 1 | J2: 0 | K2: 0.5 | L2: 1 | M2: 2 | N2: 3 | O2: 4 | P2: 5 | Q2: 6 | R2: 7 | S2: 8 | T2: 9 | U2: 10
J3: 0.5 | K3: 0.7 | L3: 0.81 | M3: 0.9 | N3: 0.92 | O3: 0.94 | P3: 0.95 | Q3: 0.955 | R3: 0.96 | S3: 0.965 | T3: 0.97 | U3: 0.975
E24: شكل 1 | Q24: شكل 2
A27: 0 | B27: 10 | C27: 20 | D27: 30 | E27: 40 | F27: 50 | I27: 0 | J27: 10 | K27: 20 | L27: 30 | M27: 40 | N27: 50
A28: 400 | B28: 480 | C28: 510 | D28: 540 | E28: 560 | F28: 565 | I28: 200 | J28: 250 | K28: 270 | L28: 290 | M28: 300 | N28: 305
A29: 600 | B29: 680 | C29: 710 | D29: 740 | E29: 760 | F29: 765 | I29: 300 | J29: 350 | K29: 370 | L29: 400 | M29: 420 | N29: 430
A30: 800 | B30: 880 | C30: 915 | D30: 950 | E30: 960 | F30: 955 | I30: 400 | J30: 450 | K30: 480 | L30: 510 | M30: 530 | N30: 540
A31: 1000 | B31: 1100 | C31: 1200 | D31: 1245 | E31: 1285 | F31: 1300 | I31: 500 | J31: 575 | K31: 640 | L31: 680 | M31: 720 | N31: 750
A32: 1200 | B32: 1300 | C32: 1400 | D32: 1470 | E32: 1500 | F32: 1515 | I32: 600 | J32: 700 | K32: 750 | L32: 800 | M32: 840 | N32: 855
A33: 1400 | B33: 1500 | C33: 1600 | D33: 1680 | E33: 1700 | F33: 1695 | I33: 700 | J33: 780 | K33: 840 | L33: 875 | M33: 905 | N33: 935
A34: 1600 | B34: 1700 | C34: 1790 | D34: 1850 | E34: 1900 | F34: 1900 | I34: 800 | J34: 880 | K34: 940 | L34: 975 | M34: 1010 | N34: 1045
A35: 1800 | B35: 1910 | C35: 2000 | D35: 2070 | E35: 2105 | F35: 2120 | I35: 900 | J35: 980 | K35: 1050 | L35: 1100 | M35: 1140 | N35: 1160
A36: 2000 | B36: 2100 | C36: 2180 | D36: 2240 | E36: 2285 | F36: 2300 | I36: 1000 | J36: 1080 | K36: 1140 | L36: 1200 | M36: 1240 | N36: 1260
I37: 100 | J37: 140 | K37: 170 | L37: 185 | M37: 200 | N37: 210
K55: شكل 3
N57: جدول رقم 2
B58: n0 | C58: جدول رقم1 | J58: للقنابل الغير الموجهة V تساوي 250-300 م/ثا اما α فتساوي 20-30 درجة
B59: 1.25 | C59: لبلاطة الحماية المصنوعة من البيتون المسلح | L59: اما للقنابل الموجهة فحسب الجدول
B60: 1.5 | C60: بلاطة حمايةمن البيتون العادي/او طبقة ترابية | L60: م/ثا ,V | M60: 300-400 | N60: 400-600 | O60: 790-940
B61: n0= | L61: درجة,α | M61: 25-40 | N61: 30-45 | O61: 40-60
O62: للصواريخ
J63: V= | M63: α=
C64: جدول رقم3
A65: نوع المادة المتفجرة | C65: تريتونال 80-20 | D65: خليط v | E65: تورليكس H6 | F65: تريتونال 90/40 | G65: ايدنالود
A66: K1 | C66: 1.53 | D66: 1.34 | E66: 1.26 | F66: 1.23 | G66: 1.05
A67: K1=
H100: جدول يبين قيمة عامل الدكة حسب عمق التوضع وحسب النسبة(h/zp)
C102: بغض النظر عن قيمة (h/zp) | I102: (h/zp) عند
I103: 0.25 | K103: 0.5 | M103: 0.75 | O103: 1 | Q103: 1
B105: قيمة m | C105: 1 | E105: 1.1 | G105: 1.3 | I105: 1.35 | K105: 1.4 | M105: 1.45 | O105: 1.5 | Q105: 1.65
C110: بدون دكة
E111: بدون دكة
G112: بدون دكة
I113: بدون دكة
K114: بدون دكة
M116: بدون دكة
O119: بدون دكة | Q119: مع دكة

Sheet Sheet3
O1: عزيزي المهندس الشاطر: يتم استخدام هذا البرنامج من خلال هذه الصفحة وستكون الإدخالات والمخرجات في هذه الصفحة ولاداعي لفتح الصفحة الاولى والثانية لأن اي كتابة او تعديل سيؤدي الى تخريب البرنامج
N2: ارجو منك الالتزام بطريقة العمل حسب ماسأكتبه ادناه. القيم الموضوعة هي لحالة دراسية معينة اما انت فاختر ماتريده وستتغير الارقام والحسابات بناء على دراستك انت.
Q4: ادخل المعطيات الاساسية بعد النظر الى الجداول والرسوم وضع قيم هذه المعطيات في المربعات المخصصة باللون الاحمر | R4: A
H6: جدول 1 | Q6: القنبلة المستخدمة: ان هذه الدراسة تخص القنابل الخارقة التي تخرق مسافة معينة في بلاطة الحماية وتنفجر بعد زمن | R6: A-1
C7: نوع القنبلة | D7: عياره(فونت) | E7: الوزن,كغ | F7: الطول العام, م | G7: طول الهيكل, م | H7: قطر الهيكل,م | I7: نسبة طول الحشوة الى قطر الهيكل | K7: نسبة طول الرأس الحربي الى القطر | M7: وزن المواد المتفجرة, كغ | O7: نوع المادة المتفجرة
B8: الترميز | C8: _ | D8: _ | E8: P | F8: loб | G8: lk | H8: dk | I8: lᴈ/dk | K8: lгч/dk | M8: C | O8: _
B9: 1 | C9: AN-M30A1 | D9: 100 | E9: 61 | F9: 1.38 | G9: 0.76 | H9: 0.21 | I9: 3.6 | K9: 1 | M9: 23 | O9: تريتونال
B10: =1+B9 -> 2 | C10: AN-M57A1 | D10: 250 | E10: 131 | F10: 1.58 | G10: 0.95 | H10: 0.28 | I10: 3.4 | K10: 1 | M10: 62 | O10: تريتونال
B11: =1+B10 -> 3 | C11: AN-M64A1 | D11: 500 | E11: 264 | F11: 1.83 | G11: 1.21 | H11: 0.36 | I11: 3.3 | K11: 1 | M11: 128 | O11: تريتونال
B12: =1+B11 -> 4 | C12: M117(M) | D12: 750 | E12: 373 | F12: 2.27 | G12: 1.42 | H12: 0.41 | I12: 3.5 | K12: 1 | M12: 177 | O12: تريتونال
B13: =1+B12 -> 5 | C13: AN-M65A1 | D13: 1000 | E13: 547 | F13: 2.46 | G13: 1.37 | H13: 0.48 | I13: 2.8 | K13: 1 | M13: 270 | O13: تريتونال
B14: =1+B13 -> 6 | C14: AN-M66A1 | D14: 2000 | E14: 1033 | F14: 2.97 | G14: 1.82 | H14: 0.59 | I14: 3.1 | K14: 1 | M14: 526 | O14: تريتونال
B15: =1+B14 -> 7 | C15: _ | D15: 3000 | E15: 1383 | F15: 4.7 | G15: 3.07 | H15: 0.61 | I15: 5 | K15: 1 | M15: 816 | O15: تريتونال
B16: =1+B15 -> 8 | C16: MK81 | D16: 250 | E16: 118 | F16: 1.88 | G16: 1.18 | H16: 0.23 | I16: 5.2 | K16: 2.5 | M16: 45 | O16: تريتونال
B17: =1+B16 -> 9 | C17: MK82 | D17: 500 | E17: 241 | F17: 2.21 | G17: 1.55 | H17: 0.27 | I17: 5.7 | K17: 2.5 | M17: 87 | O17: تريتونال
B18: =1+B17 -> 10 | C18: MK83 | D18: 1000 | E18: 441 | F18: 3.01 | G18: 1.92 | H18: 0.36 | I18: 5.3 | K18: 2 | M18: 215 | O18: تريتونال
B19: =1+B18 -> 11 | C19: MK84 | D19: 2000 | E19: 894 | F19: 3.83 | G19: 2.41 | H19: 0.46 | I19: 5.2 | K19: 2 | M19: 430 | O19: تريتونال
B20: =1+B19 -> 12 | C20: MK81 سنيكاي | D20: 250 | E20: 134 | F20: 1.91 | G20: 1.19 | H20: 0.23 | I20: 5.2 | K20: 2.5 | M20: 45 | O20: تريتونال
B21: =1+B20 -> 13 | C21: MK82 سنيكاي | D21: 500 | E21: 260 | F21: 2.26 | G21: 1.55 | H21: 0.27 | I21: 5.7 | K21: 2.5 | M21: 87 | O21: تريتونال
B22: =1+B21 -> 14 | C22: M117R | D22: 750 | E22: 380 | F22: 2.21 | G22: 1.12 | H22: 0.11 | I22: 3.5 | K22: 1 | M22: 177 | O22: تريتونال
E23: 441 | F23: 3.01 | G23: 1.92 | H23: 0.36 | I23: 5.3 | K23: 2 | M23: 215
R24: ملاحظة: اذا كانت القنيلة المطلوبة غير موجودة في الجدول يجب معرفة مواصفاتها ووضعها في المربعات الحمر
F26: جدول رقم 2 | N26: جدول رقم3
B27: للقنابل الغير الموجهة V تساوي 250-300 م/ثا اما α فتساوي 20-30 درجة | L27: نوع المادة المتفجرة | N27: تريتونال 80-20 | O27: خليط v | P27: تورليكس H6 | Q27: تريتونال 90/40 | R27: ايدنالود
D28: اما للقنابل الموجهة فحسب الجدول | L28: معامل المادة المتفجرة-K1 | N28: 1.639 | O28: 1.34 | P28: 1.26 | Q28: 1.23 | R28: 1.05
D29: م/ثا ,V | E29: 300-400 | F29: 400-600 | G29: 790-940 | L29: K1= | M29: 1.639
D30: درجة,α | E30: 25-40 | F30: 30-45 | G30: 40-60 | R30: جدول 3 يبين قوة المادة المتفجرة في القنبلة منسوبا الى التراتيل
G31: للصواريخ
B32: V= | C32: 350 | E32: α= | F32: 20
J34: جدول 2 يبين السرعة الابتدائية لسقوط القنبلة وزاوية الميل عن الشاقول عند الاصطدام بالارض
Q35: مواصفات والمعاملات الخاصة بالتربة والبيتون و حديد التسليح | R35: A-2
N37: n0 | O37: جدول رقم4
G38: جدول رقم 5 | N38: 1.25 | O38: لبلاطة الحماية المصنوعة من البيتون المسلح
C39: نوع المادة | G39: معامل الاختراق | I39: معامل التصدع من جهة الانفجار | K39: معامل التدمير | L39: معامل التصدع من الجهة المعاكسة | N39: 1.5 | O39: بلاطة حمايةمن البيتون العادي/او طبقة ترابية قاسية
E40: الترميز | G40: Kпp | I40: Kв | K40: Kp | M40: Kot | N40: n0= | O40: 1.25
C41: طين رخو مشبع بالماء | G41: 1.3e-05 | I41: 0.6 | K41: 0.85 | M41: _ | R41: جدول 4 يبين قيمة معامل الاحتياط عند حساب سماكة بلاطة الحماية
C42: طين متوسط الكثافة | G42: 7e-06 | I42: 0.5 | K42: 0.6 | M42: _
C43: طبقة طينية طبيعية مع وجود احجار في تشكيلها | G43: 6e-06 | I43: 0.5 | K43: 0.6 | M43: _
C44: طبقة رمل مخلط بالشوائب | G44: 5e-06 | I44: 0.5 | K44: 0.6 | M44: _
C45: طبقة رمل نقي طبيعي/او طبقة كلسية مفتتة | G45: 4.5e-06 | I45: 0.5 | K45: 0.63 | M45: _
...
